<mujoco>
  <option gravity="0 0 -9.81" />
  <worldbody>
    <body name="object_3" pos="1 0 2" />
    <body name="object_1" pos="0.5 0 1.5">
      <geom type="box" size="0.1 0.4 0.1" pos="0 0.2 0" density="1" rgba="0.7 0.7 0.7 1" />
      <geom type="box" size="0.4 0.1 0.1" pos="0.2 0 0" density="1" rgba="0.7 0.7 0.7 1" />
      <joint type="ball" name="object_1_joint" limited="false" />
    </body>
  <body name="support_point" pos="0.7 0.0 2.0"><geom type="sphere" size="1000.0" rgba="1 0 0 1" /></body><body name="support_point" pos="0.3 0.2 2.0"><geom type="sphere" size="1000.0" rgba="1 0 0 1" /></body></worldbody>
<joint name="joint_object_2_object_1" type="revolute" body1="object_2" body2="object_1" /></mujoco>