<mujoco>
  <option gravity="0 0 -9.81" />
  <worldbody>
    <body name="object_5" pos="0 0 -10">
      <geom type="plane" size="30 30 0.1" rgba="0.7 0.7 0.7 1" />
    </body>
    <body name="object_4" pos="0 0 0.5">
      <geom type="box" size="5 0.2 0.1" density="0.5" rgba="0.7 0.7 0.7 1" />
      <joint name="object_4_joint" type="hinge" axis="0 1 0" />
    </body>
    <body name="object_1" pos="-3 0 1">
      <geom type="sphere" size="0.3" density="2" rgba="0.7 0.7 0.7 1" />
    </body>
    <body name="object_2" pos="3 0 1">
      <geom type="sphere" size="0.3" density="1" rgba="0.7 0.7 0.7 1" />
    </body>
    <body name="object_3" pos="0 0 2">
      <geom type="sphere" size="0.3" density="1.5" rgba="0.7 0.7 0.7 1" />
    </body>
  <body name="balancing_mass" pos="2.0 0.0 0.65"><geom type="sphere" size="1.5" rgba="0.7 0.7 0.7 1" /></body></worldbody>
</mujoco>