<mujoco>
  <option gravity="0 0 -9.81" />
  <worldbody>
    <body name="object_4" pos="0 0 -10">
      <geom type="plane" size="30 30 0.1" rgba="0.7 0.7 0.7 1" />
    </body>
    <body name="object_3" pos="0 0 0">
      <geom type="sphere" size="0.1" rgba="0.7 0.7 0.7 1" />
    </body>
    <body name="object_1" pos="-3 0 1">
      <geom type="capsule" fromto="-0.5 0 0 0.5 0 0" size="0.05" density="0.2" rgba="0.7 0.7 0.7 1" />
      <geom type="sphere" pos="-0.3 0 0" size="0.1" density="1" rgba="0.7 0.7 0.7 1" />
      <geom type="sphere" pos="0.3 0 0" size="0.1" density="1" rgba="0.7 0.7 0.7 1" />
      <joint name="object_1_joint" type="hinge" axis="0 0 1" />
    </body>
    <body name="object_2" pos="3 0 1">
      <geom type="capsule" fromto="-0.5 0 0 0.5 0 0" size="0.05" density="0.2" rgba="0.7 0.7 0.7 1" />
      <geom type="sphere" pos="-0.5 0 0" size="0.1" density="1" rgba="0.7 0.7 0.7 1" />
      <geom type="sphere" pos="0.5 0 0" size="0.1" density="1" rgba="0.7 0.7 0.7 1" />
      <joint name="object_2_joint" type="hinge" axis="0 0 1" />
    </body>
  </worldbody>
</mujoco>