<mujoco>
  <option gravity="0 0 -9.81" />
  <worldbody>
    <body name="object_4" pos="0 0 -1">
      <geom type="plane" size="20 20 0.1" rgba="0.9 0.9 0.9 1" />
    </body>
    <body name="object_3" pos="0 0 0">
      <site name="anchor_site" pos="0 0 0" size="0.01" />
    </body>
    <body name="object_1" pos="-1 0 0">
      <geom type="box" size="0.2 0.2 0.2" mass="2" rgba="1 0 0 1" />
      <joint name="object_1_joint" type="slide" axis="1 0 0" />
      <site name="block_1_site" pos="0 0 0" size="0.01" />
    </body>
    <body name="object_2" pos="1 0 0">
      <geom type="box" size="0.2 0.2 0.2" mass="1" rgba="0 0 1 1" />
      <joint name="object_2_joint" type="slide" axis="1 0 0" />
      <site name="block_2_site" pos="0 0 0" size="0.01" />
    </body>
    <body name="object_5" pos="0 0 1" />
  </worldbody>
  <tendon>
    <spatial name="spring1" width="0.01" stiffness="50">
      <site site="anchor_site" />
      <site site="block_1_site" />
    </spatial>
    <spatial name="spring2" width="0.01" stiffness="100">
      <site site="anchor_site" />
      <site site="block_2_site" />
    </spatial>
  </tendon>
<joint name="joint_object_1_object_3" type="revolute" body1="object_1" body2="object_3" /><joint name="joint_object_2_object_3" type="revolute" body1="object_2" body2="object_3" /></mujoco>