<mujoco>
  <option gravity="0 0 -9.81" />
  <worldbody>
    <light diffuse="0.5 0.5 0.5" pos="0 0 5" dir="0 0 -1" />
    <body name="object_4" pos="0 0 -10">
      <geom type="plane" size="50 50 0.1" rgba="0.9 0.9 0.9 1" friction="1 1 1" />
    </body>
    <body name="object_3" pos="0 0 2">
      <geom type="sphere" size="0.2" rgba="0.2 0.2 0.2 1" />
    </body>
    <body name="object_1" pos="-1 0 1">
      <geom type="box" size="0.4 0.4 0.4" mass="5" rgba="1 0 0 1" />
      <joint type="free" name="object_1_joint" />
    </body>
    <body name="object_2" pos="1 0 1">
      <geom type="box" size="0.4 0.4 0.4" mass="2" rgba="0 1 0 1" />
      <joint type="free" name="object_2_joint" />
    </body>
  </worldbody>
<joint name="joint_object_1_object_2" type="revolute" body1="object_1" body2="object_2" /></mujoco>