<mujoco>
  <option gravity="0 0 -9.81" />
  <worldbody>
    
    <body name="object_1" pos="0 0 1">
      <geom type="capsule" fromto="0 0 0 0 0 -1" size="0.1" rgba="0.7 0.7 0.7 1" />
      <joint name="object_1_joint" type="free" />
    </body>
    
    <body name="object_2" pos="0 0 0">
      <geom type="box" size="0.3 0.3 0.3" rgba="0.7 0.7 0.7 1" />
    </body>
  <body name="arm_left_in" pos="-0.2 0.0 1.5"><geom type="sphere" size="500" rgba="0.2 0.8 0.2 1.0" /></body><body name="arm_right_in" pos="0.2 0.0 1.5"><geom type="sphere" size="500" rgba="0.2 0.8 0.2 1.0" /></body></worldbody>
<joint name="joint_left_arm_object_1" type="revolute" body1="left_arm" body2="object_1" /><joint name="joint_right_arm_object_1" type="revolute" body1="right_arm" body2="object_1" /><joint name="joint_arm_left_extended_object_1" type="revolute" body1="arm_left_extended" body2="object_1" /><joint name="joint_arm_right_extended_object_1" type="revolute" body1="arm_right_extended" body2="object_1" /></mujoco>