<mujoco>
  <!-- Task guidance: The amplitude is the maximum offset of the mass from the spring reference position at the start of the trial. Query or observe the scene state to measure that offset, then return only the numeric amplitude. -->
  <option gravity="0 0 -9.81" />
  <worldbody>
    <body name="object_1" pos="0.2 0 0">
      <geom type="sphere" size="0.5" density="5" rgba="1 0 0 1" />
      <joint name="object_1_joint" type="free" />
    </body>
    <body name="object_2" pos="0 0 0">
      <geom type="cylinder" size="0.1 2" density="3" rgba="0 1 0 1" />
      <joint name="object_2_joint" type="hinge" axis="0 0 1" />
    </body>
    <body name="object_3" pos="0 0 -10">
      <geom type="plane" size="30 30 0.1" rgba="0.7 0.7 0.7 1" friction="1 1 1" />
    </body>
  </worldbody>
</mujoco>