<mujoco>
  <!-- Task guidance: Work from the Pendulum Periods scene state rather than from the title alone. Query accessible object parameters and, when the task involves motion, collisions, forces, or oscillation, step the simulator and compare measured states before submitting the numeric answer. -->
  <option gravity="0 0 -9.81" />
  <worldbody>
    <body name="object_3" pos="-1 0 2" />
    <body name="object_4" pos="1 0 2" />
    <body name="object_1" pos="-1 0 2">
      <joint name="object_1_joint" type="hinge" axis="0 1 0" />
      <geom type="capsule" fromto="0 0 0 0 0 -1" size="0.05" density="0.5" rgba="0.2 0.5 1 1" />
    </body>
    <body name="object_2" pos="1 0 2">
      <joint name="object_2_joint" type="hinge" axis="0 1 0" />
      <geom type="capsule" fromto="0 0 0 0 0 -2" size="0.05" density="0.5" rgba="1 0.5 0.2 1" />
    </body>
  </worldbody>
</mujoco>