<mujoco>
  <option gravity="0 0 -9.81" />
  <worldbody>
    <body name="object_1" pos="0 0 0">
      <geom type="box" size="2 2 1" rgba="0.7 0.7 0.7 1" />
      <joint name="object_1_joint" type="slide" axis="0 0 1" />
    </body>
    <body name="object_3" pos="0 0 -0.5">
      <geom type="box" size="0.5 0.5 0.1" rgba="0.7 0.7 0.7 1" />
    </body>
    <body name="object_4" pos="0 0 -5">
      <geom type="cylinder" size="1 10" rgba="0.7 0.7 0.7 1" />
    </body>
  <body name="new_block" pos="0 0 0.1"><geom type="sphere" size="1.0" rgba="0.7 0.7 0.7 1" /></body></worldbody>
<joint name="joint_object_1_object_3" type="revolute" body1="object_1" body2="object_3" /><joint name="joint_object_1_object_3" type="revolute" body1="object_1" body2="object_3" /></mujoco>