<mujoco>
  <option gravity="0 0 -9.81" />
  <worldbody>
    <body name="object_2" pos="0 0 2" />
    <body name="object_3" pos="1 0 2" />
    <body name="object_1" pos="0.5 0 1.5">
      <geom type="box" size="0.1 0.4 0.1" pos="0 0.2 0" density="1" rgba="0.8 0.2 0.2 1" />
      <geom type="box" size="0.4 0.1 0.1" pos="0.2 0 0" density="1" rgba="0.8 0.2 0.2 1" />
      <joint type="ball" name="object_1_joint" limited="false" />
    </body>
  <body name="anchor_A" pos="0.7 0.0 1.5"><geom type="sphere" size="1000.0" rgba="1.0 0.0 0.0 1.0" /></body><body name="anchor_B" pos="0.3 0.0 1.5"><geom type="sphere" size="1000.0" rgba="0.0 0.0 1.0 1.0" /></body></worldbody>
<joint name="joint_object_1_anchor_A" type="revolute" body1="object_1" body2="anchor_A" /><joint name="joint_object_1_anchor_B" type="revolute" body1="object_1" body2="anchor_B" /></mujoco>