<mujoco>
  <option gravity="0 0 -9.81" />
  <worldbody>
    
    <body name="object_1" pos="0 0 1">
      <geom type="capsule" fromto="0 0 0 0 0 -1" size="0.1" rgba="0.2 0.2 1 1" />
      <joint name="object_1_joint" type="free" />
    </body>
    
    <body name="object_2" pos="0 0 0">
      <geom type="box" size="0.3 0.3 0.3" rgba="0.5 0.5 0.5 1" />
    </body>
  <body name="arm1" pos="0.5 0.0 1.0"><geom type="sphere" size="1000.0" rgba="1.0 0.0 0.0 1.0" /></body><body name="arm2" pos="-0.5 0.0 1.0"><geom type="sphere" size="1000.0" rgba="0.0 1.0 0.0 1.0" /></body></worldbody>
<joint name="joint_object_1_arm1" type="revolute" body1="object_1" body2="arm1" /><joint name="joint_object_1_arm2" type="revolute" body1="object_1" body2="arm2" /></mujoco>