<mujoco>
  <option gravity="0 0 -9.81" />
  <worldbody>
    <body name="object_2" pos="0 0 0">
      <geom type="cylinder" size="0.1 0.05" rgba="0.5 0.5 0.5 1" />
    </body>
    <body name="object_3" pos="0 0 1">
      <geom type="box" size="0.2 0.2 0.2" rgba="0.6 0.6 0.6 1" />
    </body>
    <body name="object_4" pos="-10 0 -0.1">
      <geom type="plane" size="30 30 0.1" rgba="0.7 0.7 0.7 1" friction="0.5 0.5 0.5" />
    </body>
    <body name="object_1" pos="2 0 1">
      <geom type="box" size="0.2 1 2" density="1" rgba="0.2 0.4 0.8 1" />
      <joint name="object_1_joint" type="hinge" axis="0 0 1" />
    </body>
  </worldbody>
<joint name="joint_object_1_object_2" type="revolute" body1="object_1" body2="object_2" /><joint name="joint_object_2_object_4" type="revolute" body1="object_2" body2="object_4" /><joint name="joint_object_1_object_2" type="revolute" body1="object_1" body2="object_2" /></mujoco>