<mujoco>
  <option gravity="0 0 -9.81" />
  <worldbody>
    <body name="object_3" pos="-2 0 0.1">
      <geom type="capsule" fromto="0 0 0 0 0 0.4" size="0.05" rgba="0.5 0.5 1 1" />
    </body>
    <body name="object_1" pos="-2 0 0.6">
      <geom type="box" size="0.1 0.1 0.1" density="1" rgba="0 1 0 1" />
      <joint type="slide" axis="0 0 1" name="object_1_joint" />
    </body>
    <body name="object_4" pos="2 0 0.1">
      <geom type="capsule" fromto="0 0 0 0 0 0.4" size="0.05" rgba="1 0.5 0.5 1" />
    </body>
    <body name="object_2" pos="2 0 0.6">
      <geom type="box" size="0.1 0.1 0.1" density="1" rgba="0 0 1 1" />
      <joint type="slide" axis="0 0 1" name="object_2_joint" />
    </body>
  </worldbody>
<joint name="joint_object_1_object_3" type="revolute" body1="object_1" body2="object_3" /><joint name="joint_object_2_object_4" type="revolute" body1="object_2" body2="object_4" /><joint name="joint_object_1_object_3" type="revolute" body1="object_1" body2="object_3" /><joint name="joint_object_2_object_4" type="revolute" body1="object_2" body2="object_4" /></mujoco>