<mujoco model="spring_scale">
    <compiler angle="radian" />
    <option gravity="0 0 -9.81" />  

    <worldbody>
        
        <geom name="ground" type="plane" pos="0 0 0" size="2 2 0.1" rgba="0.7 0.7 0.7 1" friction="1 1 1" />

        
        <body name="object_1" pos="0 0 1">
            <geom type="sphere" size="0.05" rgba="0 0 1 1" />  
            <site name="anchor_site" pos="0 0 0" />

            
            <body name="object_2" pos="0 0 -0.3">
                <joint name="slider_joint" type="slide" axis="0 0 1" damping="1" />
                <geom type="cylinder" size="0.05 0.02" rgba="0 1 0 1" />  
                <site name="slider_site" pos="0 0 0" />
            </body>
        </body>

        
        </worldbody>

    
    <tendon>
        
        <spatial name="spring1" range="0.3 0.7" stiffness="50" damping="2">
            <site site="anchor_site" />
            <site site="slider_site" />
        </spatial>
    </tendon>
</mujoco>