<mujoco>
  <option gravity="0 0 -9.81" />
  <worldbody>
    <body name="object_1" pos="-3 0 0.2">
      <geom type="box" size="0.3 0.3 0.3" density="1" rgba="0 0.7 1 1" />
      <joint name="object_1_joint" type="slide" axis="1 0 0" />
    </body>
    <body name="object_2" pos="3 0 0.2">
      <geom type="box" size="0.3 0.3 0.3" density="1" rgba="1 0.4 0.4 1" />
      <joint name="object_2_joint" type="slide" axis="1 0 0" />
    </body>
  <body name="new_low_friction" pos="3.0 -1.0 0.0"><geom type="sphere" size="1.0" rgba="0.8 0.8 0.8 1" /></body><body name="new_high_friction" pos="3.0 1.0 0.0"><geom type="sphere" size="1.0" rgba="0.5 0.5 0.5 1" /></body></worldbody>
</mujoco>