<mujoco>
  <option gravity="0 0 -9.81" />
  <worldbody>
    
    <body name="object_3" pos="0 0 1">
      <geom type="box" size="0.2 0.2 0.2" rgba="0.6 0.6 0.6 1" />
      <site name="support_site" pos="-0.2 0 0" size="0.01" />
    </body>
    
    <body name="object_4" pos="-10 0 -0.1">
      <geom type="plane" size="25 25 0.1" rgba="0.8 0.8 0.8 1" friction="0.1 0.1 0.1" />
    </body>
    
    <body name="object_1" pos="-3 0 1">
      <geom type="box" size="0.3 0.3 0.3" mass="1" rgba="0.2 0.8 0.2 1" />
      <joint name="object_1_joint" type="free" />
      <site name="mass_site" pos="0.3 0 0" size="0.01" />
    </body>
    
    <body name="object_2" pos="0 0 1">
      <geom type="capsule" fromto="0 0 0 -3 0 0" size="0.05" rgba="0.8 0.8 0.2 1" />
    </body>
  </worldbody>

  
  <tendon>
    <spatial limited="true" range="0 5" stiffness="50" width="0.02">
      <site site="mass_site" />
      <site site="support_site" />
    </spatial>
  </tendon>
<joint name="joint_object_1_object_3" type="revolute" body1="object_1" body2="object_3" /></mujoco>