<mujoco>
  <option gravity="0 0 -9.81" />
  <worldbody>
    <body name="object_2" pos="0 0 2" />
    <body name="object_3" pos="1 0 2" />
    <body name="object_1" pos="0.5 0 1.5">
      <geom type="box" size="0.1 0.4 0.1" pos="0 0.2 0" density="1" rgba="0.8 0.2 0.2 1" />
      <geom type="box" size="0.4 0.1 0.1" pos="0.2 0 0" density="1" rgba="0.8 0.2 0.2 1" />
      <joint type="ball" name="object_1_joint" limited="false" />
    </body>
  <body name="ground" pos="0.0 0.0 0.0"><geom type="sphere" size="0.0" rgba="0.5 0.5 0.5 1.0" /></body></worldbody>
<joint name="joint_hook_object_1" type="revolute" body1="hook" body2="object_1" /><joint name="joint_hook1_object_1" type="revolute" body1="hook1" body2="object_1" /><joint name="joint_hook_A_object_1" type="revolute" body1="hook_A" body2="object_1" /><joint name="joint_hook_B_object_1" type="revolute" body1="hook_B" body2="object_1" /></mujoco>