<mujoco>
  <option gravity="0 0 -9.81" />
  <worldbody>
    <body name="object_1" pos="0 0 0">
      <geom type="cylinder" size="0.1 1" density="5" rgba="1 0 0 1" />
      <joint name="object_1_joint" type="hinge" axis="0 0 1" />
    </body>
    <body name="object_2" pos="0 0 1">
      <geom type="box" size="0.5 0.25 0.25" density="2" rgba="0 0 1 1" />
      <joint name="object_2_joint" type="free" />
    </body>
    <body name="object_3" pos="0 0 -10">
      <geom type="plane" size="30 30 0.1" rgba="0.7 0.7 0.7 1" friction="0.5 0.5 0.5" />
    </body>
  </worldbody>
<joint name="joint_object_1_object_3" type="revolute" body1="object_1" body2="object_3" /></mujoco>