<mujoco>
  <option gravity="0 0 -9.81" />
  <worldbody>
    
    <body name="object_1" pos="-1 0 2">
      <geom type="capsule" fromto="0 0 0 0 0 -1" size="0.05" rgba="0.7 0.2 0.2 1" />
      <joint name="object_1_joint" type="hinge" axis="0 1 0" />
    </body>
    
    <body name="object_2" pos="-1 0 1">
      <geom type="capsule" fromto="0 0 0 0 0 -1" size="0.05" rgba="0.2 0.2 0.7 1" />
      <joint name="object_2_joint" type="hinge" axis="0 1 0" />
    </body>
    
    <body name="object_3" pos="0 0 2">
      <geom type="sphere" size="0.2" rgba="0.5 0.5 0.5 1" />
    </body>
  </worldbody>
<joint name="joint_object_3_object_1" type="revolute" body1="object_3" body2="object_1" /><joint name="joint_object_1_object_2" type="revolute" body1="object_1" body2="object_2" /></mujoco>