<mujoco>
  <option gravity="0 0 -9.81" />
  <worldbody>
    <body name="object_1" pos="0 0 5">
      <geom type="box" size="0.5 0.5 0.5" density="5" rgba="1 0 0 1" />
      <joint name="object_1_joint" type="free" />
    </body>
    <body name="object_2" pos="0 0 0">
      <geom type="box" size="0.5 0.5 0.5" density="3" rgba="0 1 0 1" />
      <joint name="object_2_joint" type="free" />
    </body>
    <body name="object_3" pos="0 0 4">
      <geom type="sphere" size="0.2" density="2" rgba="0 0 1 1" />
      <joint name="object_3_joint" type="hinge" axis="0 0 1" />
    </body>
    <body name="object_4" pos="0 0 -10">
      <geom type="plane" size="30 30 0.1" rgba="0.7 0.7 0.7 1" friction="1 1 1" />
    </body>
  </worldbody>
<joint name="joint_object_1_object_3" type="revolute" body1="object_1" body2="object_3" /><joint name="joint_object_2_object_3" type="revolute" body1="object_2" body2="object_3" /></mujoco>