<mujoco model="mass_spring_system">
    <option gravity="0 0 -9.81" />
    
    <worldbody>
        <light diffuse=".5 .5 .5" pos="0 0 3" dir="0 0 -1" />
        <geom type="plane" size="5 5 0.1" rgba=".9 .9 .9 1" />
        
        <body name="object_1" pos="0 0 2">
            <geom type="sphere" size="0.05" rgba="0.8 0.8 0.8 1" />
            <joint type="free" name="object_1_joint" />
            <site name="anchor_site" pos="0 0 0" size="0.01" />
        </body>
        
        <body name="object_2" pos="1 0 2">
            <joint type="free" name="object_2_joint" />
            <geom type="sphere" size="0.1" mass="1" rgba="0.8 0.2 0.2 1" />
            <site name="mass_site" pos="0 0 0" size="0.01" />
        </body>
    </worldbody>
    
    <tendon>
        <spatial limited="true" range="0 2" width="0.01">
            <site site="anchor_site" />
            <site site="mass_site" />
        </spatial>
    </tendon>
    
    <equality>
        <connect anchor="0 0 0" body1="object_1" body2="object_2" solimp="0.95 0.99 0.001" solref="0.01 1" />
    </equality>
    
    <actuator>
        <motor site="mass_site" gear="1 0 0 0 0 0" name="force_actuator" />
    </actuator>
    
    <sensor>
        <framepos objtype="site" objname="mass_site" />
        <framelinvel objtype="site" objname="mass_site" />
    </sensor>
<joint name="joint_object_1_object_2" type="revolute" body1="object_1" body2="object_2" /></mujoco>