<mujoco>
  <!-- Task guidance: Use the elevator, block, and scale setup to compare apparent weight with ordinary weight. Observe the elevator or scale response during motion before selecting the numeric direction code. -->
  <option gravity="0 0 -9.81" />
  <worldbody>
    <body name="object_1" pos="0 0 0">
      <geom type="box" size="2 2 1" rgba="0.8 0.8 0.8 1" />
      <joint name="object_1_joint" type="slide" axis="0 0 1" />
    </body>
    <body name="object_2" pos="0 0 1">
      <geom type="box" size="0.5 0.5 0.5" density="1" rgba="1 0 0 1" />
    </body>
    <body name="object_3" pos="0 0 -0.5">
      <geom type="box" size="0.5 0.5 0.1" rgba="0.7 0.7 0.7 1" />
    </body>
    <body name="object_4" pos="0 0 -5">
      <geom type="cylinder" size="1 10" rgba="0.3 0.3 0.3 1" />
    </body>
  </worldbody>
</mujoco>