<mujoco>
  <option gravity="0 0 -9.81"/>
  <worldbody>
    <!-- Compound Pendulum -->
    <body name="object_1" pos="0 0 2">
      <geom type="capsule" fromto="0 0 0 0 0 -1.5" size="0.05" rgba="0.2 0.6 0.8 1"/>
      <joint name="object_1_joint" type="hinge" axis="0 1 0"/>
    </body>
    <!-- Fixed Support -->
    <body name="object_2" pos="0 0 2">
      <geom type="sphere" size="0.2" rgba="0.5 0.5 0.5 1"/>
    </body>
    <!-- Ground Surface -->
    <body name="object_3" pos="-10 0 -10">
      <geom type="plane" size="25 25 0.1" rgba="0.7 0.7 0.7 1" friction="1 1 1"/>
    </body>
  </worldbody>
</mujoco>
