<mujoco>
  <option gravity="0 0 -9.81" />
  <worldbody>
    <body name="object_3" pos="-1 0 2" />
    <body name="object_4" pos="1 0 2" />
    <body name="object_1" pos="-1 0 2">
      <joint name="object_1_joint" type="hinge" axis="0 1 0" />
      <geom type="capsule" fromto="0 0 0 0 0 -1" size="0.05" density="0.5" rgba="0.7 0.7 0.7 1" />
    </body>
    <body name="object_2" pos="1 0 2">
      <joint name="object_2_joint" type="hinge" axis="0 1 0" />
      <geom type="capsule" fromto="0 0 0 0 0 -2" size="0.05" density="0.5" rgba="0.7 0.7 0.7 1" />
    </body>
  </worldbody>
</mujoco>