<mujoco>
  <option gravity="0 0 -9.81" />
  <worldbody>
    <body name="object_5" pos="0 0 -1">
      <geom type="plane" size="20 20 0.1" rgba="0.7 0.7 0.7 1" />
    </body>
    <body name="object_4" pos="0 0 3" />
    <body name="object_1" pos="-2 0 2.5">
      <geom type="capsule" fromto="0 0 0 0 0 -1.5" size="0.05" rgba="0.7 0.7 0.7 1" />
      <joint type="hinge" axis="0 1 0" pos="0 0 0" name="object_1_joint" />
    </body>
    <body name="object_2" pos="0 0 2.5">
      <geom type="capsule" fromto="0 0 0 0 0 -1.0" size="0.05" rgba="0.7 0.7 0.7 1" />
      <joint type="hinge" axis="0 1 0" pos="0 0 0" name="object_2_joint" />
    </body>
    <body name="object_3" pos="2 0 2.5">
      <geom type="capsule" fromto="0 0 0 0 0 -0.5" size="0.05" rgba="0.7 0.7 0.7 1" />
      <joint type="hinge" axis="0 1 0" pos="0 0 0" name="object_3_joint" />
    </body>
  </worldbody>
</mujoco>