<mujoco>
  <option gravity="0 0 -9.81" />
  <worldbody>
    <body name="object_4" pos="0 0 -10">
      <geom type="plane" size="30 30 0.1" rgba="0.9 0.9 0.9 1" />
    </body>
    <body name="object_3" pos="0 0 2">
      <geom type="cylinder" size="0.2 0.1" rgba="0.8 0.8 0.2 1" />
    </body>
    <body name="object_1" pos="-1 0 1">
      <geom type="box" size="0.3 0.3 0.3" density="1" rgba="0 0 1 1" />
    </body>
    <body name="object_2" pos="1 0 1">
      <geom type="box" size="0.3 0.3 0.3" density="3" rgba="1 0 0 1" />
    </body>
  </worldbody>
<joint name="joint_object_1_object_2" type="revolute" body1="object_1" body2="object_2" /><joint name="joint_object_1_object_3" type="revolute" body1="object_1" body2="object_3" /><joint name="joint_object_2_object_3" type="revolute" body1="object_2" body2="object_3" /></mujoco>