<mujoco>
  <option gravity="0 0 -9.81" />
  <worldbody>
    
    <body name="object_3" pos="0 0 2">
      <geom type="sphere" size="0.2" rgba="0.7 0.7 0.7 1" />
    </body>
  <body name="pendulum1" pos="0.707 0.0 2.707"><geom type="sphere" size="1000.0" rgba="0.7 0.7 0.7 1" /></body><body name="pendulum2" pos="1.414 0.0 3.414"><geom type="sphere" size="1000.0" rgba="0.7 0.7 0.7 1" /></body></worldbody>
<joint name="joint_object_3_object_1" type="revolute" body1="object_3" body2="object_1" /><joint name="joint_object_1_object_2" type="revolute" body1="object_1" body2="object_2" /></mujoco>