<mujoco model="create_attach_test">
    <option timestep="0.005" gravity="0 0 -9.81" />
    <worldbody>
        
        <body name="object_1" pos="0 0 0">
            <geom type="plane" size="30 30 0.1" rgba="0.7 0.7 0.7 1" friction="1 1 1" />
        </body>
    <body name="sphere" pos="0.0 0.0 1.0"><geom type="sphere" size="1.0" rgba="0.7 0.7 0.7 1" /></body><body name="box" pos="0.5 0.0 1.0"><geom type="sphere" size="1.0" rgba="0.7 0.7 0.7 1" /></body></worldbody>
<joint name="joint_sphere_box" type="revolute" body1="sphere" body2="box" /></mujoco>