<mujoco>
  <option gravity="0 0 -9.81" />
  <worldbody>
    <body name="object_3" pos="-3 0 0">
      <geom type="box" size="2 1 0.1" rgba="0.7 0.7 0.7 1" friction="0.1 0.1 0.1" />
    </body>
    <body name="object_4" pos="3 0 0">
      <geom type="box" size="2 1 0.1" rgba="0.7 0.7 0.7 1" friction="1.0 1.0 1.0" />
    </body>
    <body name="object_1" pos="-3 0 0.2">
      <geom type="box" size="0.3 0.3 0.3" density="1" rgba="0.7 0.7 0.7 1" />
      <joint name="object_1_joint" type="slide" axis="1 0 0" />
    </body>
    <body name="object_2" pos="3 0 0.2">
      <geom type="box" size="0.3 0.3 0.3" density="1" rgba="0.7 0.7 0.7 1" />
      <joint name="object_2_joint" type="slide" axis="1 0 0" />
    </body>
  </worldbody>
</mujoco>