<mujoco>
  <option gravity="0 0 -9.81" />
  <worldbody>
    
    <body name="object_1" pos="0 0 2">
      <geom type="sphere" size="0.3" density="1" rgba="0.8 0.3 0.3 1" />
      <joint name="object_1_joint" type="free" />
    </body>
    
    <body name="object_2" pos="0 0 3">
      <geom type="capsule" fromto="0 0 0 0 0 -1" size="0.03" rgba="0.8 0.8 0.8 1" />
    </body>
    
    <body name="object_3" pos="0 0 3">
      <geom type="box" size="0.2 0.2 0.2" rgba="0.5 0.5 0.5 1" />
    </body>
  </worldbody>
<joint name="joint_object_1_object_2" type="revolute" body1="object_1" body2="object_2" /></mujoco>