<mujoco>
  <option gravity="0 0 -9.81" />
  <worldbody>
    
    <body name="object_1" pos="-5 0 2">
      <geom type="capsule" fromto="0 0 0 0 0 -1.5" size="0.05" rgba="0.7 0.7 0.7 1" />
      <joint name="object_1_joint" type="hinge" axis="0 1 0" />
    </body>
    
    <body name="object_2" pos="5 0 1">
      <geom type="box" size="0.5 0.5 0.5" density="1" rgba="0.7 0.7 0.7 1" friction="0 0 0" />
      <joint name="object_2_joint" type="free" />
    </body>
    
    <body name="object_3" pos="0 0 0">
      <geom type="plane" size="5 10 0.1" rgba="0.7 0.7 0.7 1" friction="0 0 0" quat="0.5 0.86 0 0" />
    </body>
    
    <body name="object_4" pos="-10 0 -10">
      <geom type="plane" size="30 30 0.1" rgba="0.7 0.7 0.7 1" friction="1 1 1" />
    </body>
  </worldbody>
</mujoco>