<mujoco>
  <option gravity="0 0 -9.81" />
  <worldbody>
    <body name="object_3" pos="0 0 0">
      <geom type="plane" size="20 20 0.1" rgba="0.6 0.6 0.6 1" />
    </body>
    <body name="object_1" pos="-2 0 0.5">
      <geom type="box" size="1 0.1 0.1" mass="1" rgba="0.8 0.2 0.2 1" />
      <joint type="hinge" axis="0 0 1" name="object_1_joint" />
    </body>
    <body name="object_2" pos="2 0 0.5">
      <geom type="box" size="0.5 0.1 0.1" mass="1" rgba="0.2 0.2 0.8 1" />
      <joint type="hinge" axis="0 0 1" name="object_2_joint" />
    </body>
    <body name="object_4" pos="0 0 2" />
  </worldbody>
</mujoco>