<mujoco>
  <option gravity="0 0 -9.81" />
  <worldbody>
    <body name="object_4" pos="0 0 -10">
      <geom type="plane" size="30 30 0.1" rgba="0.9 0.9 0.9 1" />
    </body>
    <body name="object_3" pos="0 0 0">
      <geom type="box" size="10 0.2 0.1" density="0.1" rgba="0.6 0.6 0.6 1" />
    </body>
    <body name="object_1" pos="-5 0 0.3">
      <geom type="box" size="0.3 0.3 0.3" density="0.5" rgba="0 1 0 1" />
      <joint name="object_1_joint" type="slide" axis="1 0 0" />
    </body>
    <body name="object_2" pos="5 0 0.3">
      <geom type="box" size="0.3 0.3 0.3" density="5.0" rgba="1 0 0 1" />
      <joint name="object_2_joint" type="slide" axis="1 0 0" />
    </body>
  </worldbody>
</mujoco>