<mujoco>
  <!-- Task guidance: Work from the Center of Mass Determination scene state rather than from the title alone. Query accessible object parameters and, when the task involves motion, collisions, forces, or oscillation, step the simulator and compare measured states before submitting the numeric answer. -->
  <option gravity="0 0 -9.81" />
  <worldbody>
    <body name="object_2" pos="0 0 2" />
    <body name="object_3" pos="1 0 2" />
    <body name="object_1" pos="0.5 0 1.5">
      <geom type="box" size="0.1 0.4 0.1" pos="0 0.2 0" density="1" rgba="0.8 0.2 0.2 1" />
      <geom type="box" size="0.4 0.1 0.1" pos="0.2 0 0" density="1" rgba="0.8 0.2 0.2 1" />
      <joint type="ball" name="object_1_joint" limited="false" />
    </body>
  </worldbody>
</mujoco>