<mujoco>
  <!-- Task guidance: Work from the Damped Oscillations scene state rather than from the title alone. Query accessible object parameters and, when the task involves motion, collisions, forces, or oscillation, step the simulator and compare measured states before submitting the numeric answer. -->
  <option gravity="0 0 -9.81"/>
  <worldbody>
    <body name="object_4" pos="0 0 -1">
      <geom type="plane" size="30 30 0.1" rgba="0.9 0.9 0.9 1"/>
    </body>
    <body name="object_5" pos="0 0 2">
      <site name="anchor_site" pos="0 0 0" size="0.01"/>
    </body>
    <body name="object_1" pos="-1 0 1.5">
      <geom type="sphere" size="0.1" mass="1" rgba="1 0 0 1"/>
      <joint name="object_1_joint" type="slide" axis="0 0 1"/>
      <site name="mass_1_site" pos="0 0 0" size="0.01"/>
    </body>
    <body name="object_2" pos="0 0 1.5">
      <geom type="sphere" size="0.1" mass="1" rgba="0 1 0 1"/>
      <joint name="object_2_joint" type="slide" axis="0 0 1"/>
      <site name="mass_2_site" pos="0 0 0" size="0.01"/>
    </body>
    <body name="object_3" pos="1 0 1.5">
      <geom type="sphere" size="0.1" mass="1.5" rgba="0 0 1 1"/>
      <joint name="object_3_joint" type="slide" axis="0 0 1"/>
      <site name="mass_3_site" pos="0 0 0" size="0.01"/>
    </body>
  </worldbody>
  <tendon>
    <spatial name="spring1" width="0.01" stiffness="20" damping="0.5">
      <site site="anchor_site"/>
      <site site="mass_1_site"/>
    </spatial>
    <spatial name="spring2" width="0.01" stiffness="20" damping="1.0">
      <site site="anchor_site"/>
      <site site="mass_2_site"/>
    </spatial>
    <spatial name="spring3" width="0.01" stiffness="20" damping="2.0">
      <site site="anchor_site"/>
      <site site="mass_3_site"/>
    </spatial>
  </tendon>
</mujoco>
