<mujoco>
  <!-- Task guidance: Work from the Tension in a Pulley System scene state rather than from the title alone. Query accessible object parameters and, when the task involves motion, collisions, forces, or oscillation, step the simulator and compare measured states before submitting the numeric answer. -->
  <option gravity="0 0 -9.81" />
  <worldbody>
    <body name="object_1" pos="0 0 5">
      <geom type="box" size="0.5 0.5 0.5" density="5" rgba="1 0 0 1" />
      <joint name="object_1_joint" type="free" />
    </body>
    <body name="object_2" pos="0 0 0">
      <geom type="box" size="0.5 0.5 0.5" density="3" rgba="0 1 0 1" />
      <joint name="object_2_joint" type="free" />
    </body>
    <body name="object_3" pos="0 0 4">
      <geom type="sphere" size="0.2" density="2" rgba="0 0 1 1" />
      <joint name="object_3_joint" type="hinge" axis="0 0 1" />
    </body>
    <body name="object_4" pos="0 0 -10">
      <geom type="plane" size="30 30 0.1" rgba="0.7 0.7 0.7 1" friction="1 1 1" />
    </body>
  </worldbody>
</mujoco>