<mujoco>
  <option gravity="0 0 -9.81" />
  <worldbody>
    <body name="object_5" pos="0 0 -1">
      <geom type="plane" size="30 30 0.1" rgba="0.8 0.8 0.8 1" />
    </body>
    <body name="object_4" pos="0 0 0" />
    <body name="object_1" pos="-2 0 1">
      <geom type="capsule" fromto="0 0 0 0 0 2" size="0.05" density="500" rgba="1 0 0 1" />
      <joint type="hinge" axis="0 1 0" pos="0 0 0" name="object_1_joint" />
    </body>
    <body name="object_2" pos="0 0 1">
      <geom type="capsule" fromto="0 0 0 0 0 3" size="0.05" density="500" rgba="0 1 0 1" />
      <joint type="hinge" axis="0 1 0" pos="0 0 0" name="object_2_joint" />
    </body>
    <body name="object_3" pos="2 0 1">
      <geom type="capsule" fromto="0 0 0 0 0 1.5" size="0.05" density="500" rgba="0 0 1 1" />
      <joint type="hinge" axis="0 1 0" pos="0 0 0" name="object_3_joint" />
    </body>
  </worldbody>
</mujoco>