<mujoco>
  <!-- Task guidance: Work from the Torque and Rotational Inertia scene state rather than from the title alone. Query accessible object parameters and, when the task involves motion, collisions, forces, or oscillation, step the simulator and compare measured states before submitting the numeric answer. -->
  <option gravity="0 0 -9.81" />
  <worldbody>
    <light diffuse="0.5 0.5 0.5" pos="0 0 5" dir="0 0 -1" />
    <body name="object_3" pos="0 0 -10">
      <geom type="plane" size="50 50 0.1" rgba="0.85 0.85 0.85 1" friction="1 1 1" />
    </body>
    <body name="object_1" pos="-2 0 0.5">
      <geom type="capsule" fromto="-0.5 0 0 0.5 0 0" size="0.1" mass="2" rgba="1 0 0 1" />
      <joint type="hinge" axis="0 0 1" name="object_1_joint" />
    </body>
    <body name="object_2" pos="2 0 0.5">
      <geom type="capsule" fromto="0 0 0 1 0 0" size="0.1" mass="2" rgba="0 0 1 1" />
      <joint type="hinge" axis="0 0 1" name="object_2_joint" />
    </body>
  </worldbody>
</mujoco>