<mujoco>
  <!-- Task guidance: Use the sphere and spring parameters encoded in the scene, and if needed compare simulated responses around the critical point. Return the coefficient tied to this mass-spring setup rather than a generic damping example. -->
  <option gravity="0 0 -9.81" />
  <worldbody>
    <light diffuse="0.5 0.5 0.5" pos="0 0 3" dir="0 0 -1" />
    <body name="object_1" pos="0 0 2">
      <geom type="sphere" size="0.5" density="5" rgba="1 0 0 1" />
      <joint name="object_1_joint" type="slide" axis="0 0 1" />
      <site name="object_1_site" pos="0 0 0" size="0.01" />
    </body>
    <body name="object_2" pos="0 0 3">
      <geom type="capsule" size="0.1 1.5" rgba="0 1 0 1" />
      <site name="object_2_site" pos="0 0 0" size="0.01" />
    </body>
    <body name="object_3" pos="0 0 4">
      <geom type="box" size="0.1 0.1 0.1" rgba="0.5 0.5 0.5 1" />
    </body>
  </worldbody>
  <tendon>
    <spatial name="spring" width="0.01" stiffness="50" damping="1.0">
      <site site="object_2_site" />
      <site site="object_1_site" />
    </spatial>
  </tendon>
</mujoco>
