<mujoco>
  <!-- Task guidance: Work from the Heavy vs Light Cart scene state rather than from the title alone. Query accessible object parameters and, when the task involves motion, collisions, forces, or oscillation, step the simulator and compare measured states before submitting the numeric answer. -->
  <option gravity="0 0 -9.81" />
  <worldbody>
    <body name="object_3" pos="0 0 0">
      <geom type="plane" size="30 30 0.1" rgba="0.6 0.6 0.6 1" />
    </body>
    <body name="object_1" pos="-2 0 0.5">
      <geom type="box" size="0.5 0.3 0.3" mass="10" rgba="1 0 0 1" />
      <joint type="slide" axis="1 0 0" name="object_1_joint" />
    </body>
    <body name="object_2" pos="2 0 0.5">
      <geom type="box" size="0.5 0.3 0.3" mass="2" rgba="0 0 1 1" />
      <joint type="slide" axis="1 0 0" name="object_2_joint" />
    </body>
    <body name="object_4" pos="0 0 2" />
  </worldbody>
</mujoco>