<mujoco>
  <!-- Task guidance: The two masses sit at opposite sides of the seesaw pivot. Use observed rotation or vertical position change after stepping the simulation to choose the numeric side code. -->
  <option gravity="0 0 -9.81" />
  <worldbody>
    <light diffuse="0.5 0.5 0.5" pos="0 0 5" />
    <body name="object_4" pos="0 0 -10">
      <geom type="plane" size="30 30 0.1" rgba="0.95 0.95 0.95 1" />
    </body>
    <body name="object_3" pos="0 0 1">
      <geom type="box" size="5 0.2 0.1" mass="0.1" rgba="0.6 0.3 0.1 1" />
      <joint type="hinge" axis="0 1 0" pos="0 0 1" name="object_3_joint" />
    </body>
    <body name="object_1" pos="-3 0 1.2">
      <geom type="box" size="0.3 0.3 0.3" mass="2" rgba="0.5 1 0.5 1" />
    </body>
    <body name="object_2" pos="3 0 1.2">
      <geom type="box" size="0.3 0.3 0.3" mass="4" rgba="1 0.5 0.5 1" />
    </body>
  </worldbody>
</mujoco>