<mujoco>
  <option gravity="0 0 -9.81" />
  <worldbody>
    <body name="pendulum_1" pos="-1 0 2">
      <geom type="capsule" fromto="0 0 0 0 0 -1.5" size="0.02" rgba="0.7 0.7 0.7 1" />
      <joint type="hinge" axis="0 1 0" />
    </body>
    <body name="bob_1" pos="-1 0 0.5">
      <geom type="sphere" size="0.1" mass="0.5" rgba="0.7 0.7 0.7 1" />
    </body>
    <body name="pendulum_2" pos="1 0 2">
      <geom type="capsule" fromto="0 0 0 0 0 -1.0" size="0.02" rgba="0.7 0.7 0.7 1" />
      <joint type="hinge" axis="0 1 0" />
    </body>
    <body name="bob_2" pos="1 0 1.0">
      <geom type="sphere" size="0.1" mass="0.5" rgba="0.7 0.7 0.7 1" />
    </body>
  </worldbody>
</mujoco>